<robot
  name="jr_description">
  <link
    name="base_link">
    <inertial>
      <origin
        xyz="-0.10028 8.8908E-18 -0.0063661"
        rpy="0 0 0" />
      <mass
        value="2.6045" />
      <inertia
        ixx="0.0083822"
        ixy="2.649E-18"
        ixz="-0.0011858"
        iyy="0.01652"
        iyz="-6.143E-19"
        izz="0.019903" />
    </inertial>
    <visual>
      <origin
        xyz="0 0 0"
        rpy="0 0 0" />
      <geometry>
        <mesh
          filename="package://jr_description/meshes/base_link.STL" />
      </geometry>
      <material
        name="">
        <color
          rgba="0.79216 0.81961 0.93333 1" />
      </material>
    </visual>
    <collision>
      <origin
        xyz="0 0 0"
        rpy="0 0 0" />
      <geometry>
        <mesh
          filename="package://jr_description/meshes/base_link.STL" />
      </geometry>
    </collision>
  </link>
  <link
    name="arm_base">
    <inertial>
      <origin
        xyz="-0.0254 1.43687145515159E-18 -0.0015875"
        rpy="0 0 0" />
      <mass
        value="0.032774128" />
      <inertia
        ixx="2.82202738684791E-05"
        ixy="4.12183567632782E-38"
        ixz="0"
        iyy="2.82202738684791E-05"
        iyz="0"
        izz="5.63854837879466E-05" />
    </inertial>
    <visual>
      <origin
        xyz="0 0 0"
        rpy="0 0 0" />
      <geometry>
        <mesh
          filename="package://jr_description/meshes/arm_base.STL" />
      </geometry>
      <material
        name="">
        <color
          rgba="0.792156862745098 0.819607843137255 0.933333333333333 1" />
      </material>
    </visual>
    <collision>
      <origin
        xyz="0 0 0"
        rpy="0 0 0" />
      <geometry>
        <mesh
          filename="package://jr_description/meshes/arm_base.STL" />
      </geometry>
    </collision>
  </link>
  <joint
    name="base_link_to_arm_base_joint"
    type="fixed">
    <origin
      xyz="-0.03175 0 0.020574"
      rpy="0 -1.5407E-33 1.5232E-16" />
    <parent
      link="base_link" />
    <child
      link="arm_base" />
    <axis
      xyz="0 0 0" />
  </joint>
  <link
    name="kinect_base">
    <inertial>
      <origin
        xyz="0 -2.02645682143E-17 0"
        rpy="0 0 0" />
      <mass
        value="0.0655482560000002" />
      <inertia
        ixx="0.000226422958335974"
        ixy="-5.87174898103748E-21"
        ixz="-9.30344764534043E-22"
        iyy="4.40511592093335E-06"
        iyz="-5.97297429508228E-21"
        izz="0.000229066027888534" />
    </inertial>
    <visual>
      <origin
        xyz="0 0 0"
        rpy="0 0 0" />
      <geometry>
        <mesh
          filename="package://jr_description/meshes/kinect_base.STL" />
      </geometry>
      <material
        name="">
        <color
          rgba="0.792156862745098 0.819607843137255 0.933333333333333 1" />
      </material>
    </visual>
    <collision>
      <origin
        xyz="0 0 0"
        rpy="0 0 0" />
      <geometry>
        <mesh
          filename="package://jr_description/meshes/kinect_base.STL" />
      </geometry>
    </collision>
  </link>
  <joint
    name="base_link_to_kinect_base_joint"
    type="fixed">
    <origin
      xyz="-0.17145 0 0.1571"
      rpy="1.6653E-16 -1.1584E-16 1.0229E-16" />
    <parent
      link="base_link" />
    <child
      link="kinect_base" />
    <axis
      xyz="0 0 0" />
  </joint>
  <link
    name="front_left_wheel">
    <inertial>
      <origin
        xyz="0 0 -1.73472347597681E-18"
        rpy="0 0 0" />
      <mass
        value="0.757089458454383" />
      <inertia
        ixx="0.000960828806967541"
        ixy="-4.65183370141717E-20"
        ixz="-7.52316384526264E-36"
        iyy="0.00130601486354979"
        iyz="2.1696133823104E-36"
        izz="0.000960828806967541" />
    </inertial>
    <visual>
      <origin
        xyz="0 0 0"
        rpy="0 0 0" />
      <geometry>
        <mesh
          filename="package://jr_description/meshes/front_left_wheel.STL" />
      </geometry>
      <material
        name="">
        <color
          rgba="0.792156862745098 0.819607843137255 0.933333333333333 1" />
      </material>
    </visual>
    <collision>
      <origin
        xyz="0 0 0"
        rpy="0 0 0" />
      <geometry>
        <mesh
          filename="package://jr_description/meshes/front_left_wheel.STL" />
      </geometry>
    </collision>
  </link>
  <joint
    name="base_link_to_front_left_wheel_joint"
    type="continuous">
    <origin
      xyz="0 0.1143 0"
      rpy="-1.6185E-33 4.5241E-18 2.4652E-32" />
    <parent
      link="base_link" />
    <child
      link="front_left_wheel" />
    <axis
      xyz="0 1 0" />
  </joint>
  <link
    name="front_right_wheel">
    <inertial>
      <origin
        xyz="0 -1.38777878078145E-17 -1.73472347597681E-18"
        rpy="0 0 0" />
      <mass
        value="0.757089458454383" />
      <inertia
        ixx="0.000960828806967541"
        ixy="-4.38718486817743E-21"
        ixz="-4.56924239365896E-37"
        iyy="0.00130601486354979"
        iyz="8.85585047159997E-22"
        izz="0.000960828806967541" />
    </inertial>
    <visual>
      <origin
        xyz="0 0 0"
        rpy="0 0 0" />
      <geometry>
        <mesh
          filename="package://jr_description/meshes/front_right_wheel.STL" />
      </geometry>
      <material
        name="">
        <color
          rgba="0.792156862745098 0.819607843137255 0.933333333333333 1" />
      </material>
    </visual>
    <collision>
      <origin
        xyz="0 0 0"
        rpy="0 0 0" />
      <geometry>
        <mesh
          filename="package://jr_description/meshes/front_right_wheel.STL" />
      </geometry>
    </collision>
  </link>
  <joint
    name="base_link_to_front_right_wheel_joint"
    type="continuous">
    <origin
      xyz="0 -0.1143 0"
      rpy="-4.79490768851316E-18 -2.41087784164084E-33 -2.91484050545616E-17" />
    <parent
      link="base_link" />
    <child
      link="front_right_wheel" />
    <axis
      xyz="0 1 0" />
  </joint>
  <link
    name="rear_left_wheel">
    <inertial>
      <origin
        xyz="1.3878E-17 -2.7756E-17 0"
        rpy="0 0 0" />
      <mass
        value="0.60224" />
      <inertia
        ixx="0.00065807"
        ixy="-4.1642E-20"
        ixz="-2.4074E-35"
        iyy="0.00082641"
        iyz="-8.8453E-21"
        izz="0.00065807" />
    </inertial>
    <visual>
      <origin
        xyz="0 0 0"
        rpy="0 0 0" />
      <geometry>
        <mesh
          filename="package://jr_description/meshes/rear_left_wheel.STL" />
      </geometry>
      <material
        name="">
        <color
          rgba="0.79216 0.81961 0.93333 1" />
      </material>
    </visual>
    <collision>
      <origin
        xyz="0 0 0"
        rpy="0 0 0" />
      <geometry>
        <mesh
          filename="package://jr_description/meshes/rear_left_wheel.STL" />
      </geometry>
    </collision>
  </link>
  <joint
    name="base_link_to_rear_left_wheel_joint"
    type="continuous">
    <origin
      xyz="-0.17145 0.1143 -0.00323850000000001"
      rpy="-5.25433558435984E-17 -1.07552855510562E-16 0" />
    <parent
      link="base_link" />
    <child
      link="rear_left_wheel" />
    <axis
      xyz="0 1 0" />
  </joint>
  <link
    name="rear_right_wheel">
    <inertial>
      <origin
        xyz="0 2.7756E-17 -1.7347E-18"
        rpy="0 0 0" />
      <mass
        value="0.60224" />
      <inertia
        ixx="0.00065807"
        ixy="-3.0008E-20"
        ixz="-2.4074E-35"
        iyy="0.00082641"
        iyz="-4.7922E-21"
        izz="0.00065807" />
    </inertial>
    <visual>
      <origin
        xyz="0 0 0"
        rpy="0 0 0" />
      <geometry>
        <mesh
          filename="package://jr_description/meshes/rear_right_wheel.STL" />
      </geometry>
      <material
        name="">
        <color
          rgba="0.79216 0.81961 0.93333 1" />
      </material>
    </visual>
    <collision>
      <origin
        xyz="0 0 0"
        rpy="0 0 0" />
      <geometry>
        <mesh
          filename="package://jr_description/meshes/rear_right_wheel.STL" />
      </geometry>
    </collision>
  </link>
  <joint
    name="base_link_to_rear_right_wheel_joint"
    type="continuous">
    <origin
      xyz="-0.17145 -0.1143 -0.00323849999999998"
      rpy="-2.84666251601602E-17 -1.66533453693773E-16 0" />
    <parent
      link="base_link" />
    <child
      link="rear_right_wheel" />
    <axis
      xyz="0 1 0" />
  </joint>
  <link
    name="laser">
    <inertial>
      <origin
        xyz="0 -1.0618E-17 -0.030024"
        rpy="0 0 0" />
      <mass
        value="0.14729" />
      <inertia
        ixx="8.2553E-05"
        ixy="5.2628E-21"
        ixz="-1.2749E-21"
        iyy="8.2553E-05"
        iyz="1.0852E-20"
        izz="5.5249E-05" />
    </inertial>
    <visual>
      <origin
        xyz="0 0 0"
        rpy="0 0 0" />
      <geometry>
        <mesh
          filename="package://jr_description/meshes/laser.STL" />
      </geometry>
      <material
        name="">
        <color
          rgba="0.79216 0.81961 0.93333 1" />
      </material>
    </visual>
    <collision>
      <origin
        xyz="0 0 0"
        rpy="0 0 0" />
      <geometry>
        <mesh
          filename="package://jr_description/meshes/laser.STL" />
      </geometry>
    </collision>
  </link>
  <joint
    name="base_link_to_laser_joint"
    type="fixed">
    <origin
      xyz="0.03175 0 0.077724"
      rpy="0 -1.5407E-33 1.5232E-16" />
    <parent
      link="base_link" />
    <child
      link="laser" />
    <axis
      xyz="0 0 0" />
  </joint>
  <link
    name="imu">
    <inertial>
      <origin
        xyz="-1.3878E-17 -1.2982E-18 -1.3878E-17"
        rpy="0 0 0" />
      <mass
        value="0.024581" />
      <inertia
        ixx="8.2596E-06"
        ixy="8.4979E-23"
        ixz="3.6549E-23"
        iyy="3.3038E-06"
        iyz="-6.8956E-22"
        izz="5.6165E-06" />
    </inertial>
    <visual>
      <origin
        xyz="0 0 0"
        rpy="0 0 0" />
      <geometry>
        <mesh
          filename="package://jr_description/meshes/imu.STL" />
      </geometry>
      <material
        name="">
        <color
          rgba="0.79216 0.81961 0.93333 1" />
      </material>
    </visual>
    <collision>
      <origin
        xyz="0 0 0"
        rpy="0 0 0" />
      <geometry>
        <mesh
          filename="package://jr_description/meshes/imu.STL" />
      </geometry>
    </collision>
  </link>
  <joint
    name="base_link_to_imu_joint"
    type="fixed">
    <origin
      xyz="-0.19304 0 0.093599"
      rpy="0 -1.5407E-33 1.5232E-16" />
    <parent
      link="base_link" />
    <child
      link="imu" />
    <axis
      xyz="0 0 0" />
  </joint>
</robot>
